#VRML_SIM R2023a utf8

EXTERNPROTO "../protos/Encoder.proto"
EXTERNPROTO "../protos/EncoderDisk.proto"
EXTERNPROTO "https://raw.githubusercontent.com/cyberbotics/webots/R2023a/projects/objects/floors/protos/Floor.proto"
EXTERNPROTO "https://raw.githubusercontent.com/cyberbotics/webots/R2023a/projects/objects/backgrounds/protos/TexturedBackground.proto"
EXTERNPROTO "https://raw.githubusercontent.com/cyberbotics/webots/R2023a/projects/objects/backgrounds/protos/TexturedBackgroundLight.proto"

WorldInfo {
  basicTimeStep 1
}
Viewpoint {
  orientation -0.22720890101419608 -0.0430395715577552 0.9728945012590245 3.509
  position 0.495 0.222 1.25
}
TexturedBackground {
}
TexturedBackgroundLight {
}
DirectionalLight {
  direction -1 0 -1
}
Floor {
}
DEF MOTOR Robot {
  translation 0 0 1
  children [
    DEF BODY Solid {
      rotation 0 1 0 1.57079632679
      children [
        Shape {
          appearance Appearance {
            material Material {
            }
          }
          geometry Cylinder {
            height 0.1
            radius 0.05
          }
        }
      ]
    }
    DEF JOINT HingeJoint {
      jointParameters HingeJointParameters {
        dampingConstant 0.01
      }
      device [
        RotationalMotor {
          maxTorque 0.1
        }
        PositionSensor {
        }
      ]
      endPoint Solid {
        children [
          DEF SHAFT_SHAPE Transform {
            translation 0.05 0 0
            rotation 0 1 0 1.57079632679
            children [
              Shape {
                appearance Appearance {
                  material Material {
                  }
                }
                geometry Cylinder {
                  height 0.1
                  radius 0.002
                }
              }
            ]
          }
          EncoderDisk {
            translation 0.09 0 0
            appearance Appearance {
              material Material {
                diffuseColor 0.3 0.3 0.3
              }
            }
            physics Physics {
              density -1
              mass 1
            }
            radius 0.05
            thickness 0.001
            innerBeltRadius 0.02
            outerBeltRadius 0.04
            belt [
              "00000000000000000000000000000000000000000000000000000000000000001111111111111111111111111111111111111111111111111111111111111111"
              "00000000000000000000000000000000111111111111111111111111111111111111111111111111111111111111111100000000000000000000000000000000"
              "00000000000000001111111111111111111111111111111100000000000000000000000000000000111111111111111111111111111111110000000000000000"
              "00000000111111111111111100000000000000001111111111111111000000000000000011111111111111110000000000000000111111111111111100000000"
              "00001111111100000000111111110000000011111111000000001111111100000000111111110000000011111111000000001111111100000000111111110000"
              "00111100001111000011110000111100001111000011110000111100001111000011110000111100001111000011110000111100001111000011110000111100"
              "01100110011001100110011001100110011001100110011001100110011001100110011001100110011001100110011001100110011001100110011001100110"
            ]
            beltError [
              0.01, -0.01, -0.02, 0.01, -0.01, 0.02, -0.01
            ]
          }
          Transform {
            translation 0.0906 0 0
            rotation 0 1 0 1.57079632679
            children [
              Transform {
                rotation 0 0 1 1.57079632679
                children [
                  Shape {
                    appearance Appearance {
                      texture ImageTexture {
                        url [
                          "textures/NDSU-logo.dwnld.jpg"
                        ]
                      }
                    }
                    geometry Plane {
                      size 0.03 0.02
                    }
                  }
                ]
              }
            ]
          }
        ]
        name "solid(1)"
        boundingObject USE SHAFT_SHAPE
        physics Physics {
          density -1
          mass 0.1
        }
      }
    }
  ]
  controller "supervisor_position"
  supervisor TRUE
}
DEF ENCODER Robot {
  translation 0.09 0 1
  children [
    Encoder {
      ledAppearance Appearance {
        material Material {
          diffuseColor 0 0 0
          transparency 0.5
        }
      }
      distance 0.03
      innerBeltRadius 0.02
      outerBeltRadius 0.04
      numLED 7
    }
  ]
  name "encoder"
  controller "lab2.3.absolute_encoder_gray"
  controllerArgs [
    "7"
  ]
}
